[2025-10-24T01:04:56.472+0000] {taskinstance.py:1083} INFO - Dependencies all met for <TaskInstance: data_pipeline_dag.process_NOAA_weather manual__2025-10-24T01:03:11.752846+00:00 [queued]>
[2025-10-24T01:04:56.476+0000] {taskinstance.py:1083} INFO - Dependencies all met for <TaskInstance: data_pipeline_dag.process_NOAA_weather manual__2025-10-24T01:03:11.752846+00:00 [queued]>
[2025-10-24T01:04:56.477+0000] {taskinstance.py:1279} INFO - 
--------------------------------------------------------------------------------
[2025-10-24T01:04:56.477+0000] {taskinstance.py:1280} INFO - Starting attempt 1 of 1
[2025-10-24T01:04:56.477+0000] {taskinstance.py:1281} INFO - 
--------------------------------------------------------------------------------
[2025-10-24T01:04:56.483+0000] {taskinstance.py:1300} INFO - Executing <Task(PythonOperator): process_NOAA_weather> on 2025-10-24 01:03:11.752846+00:00
[2025-10-24T01:04:56.486+0000] {standard_task_runner.py:55} INFO - Started process 338 to run task
[2025-10-24T01:04:56.489+0000] {standard_task_runner.py:82} INFO - Running: ['***', 'tasks', 'run', 'data_pipeline_dag', 'process_NOAA_weather', 'manual__2025-10-24T01:03:11.752846+00:00', '--job-id', '21', '--raw', '--subdir', 'DAGS_FOLDER/data_pipeline_dag.py', '--cfg-path', '/tmp/tmp0j7md4at']
[2025-10-24T01:04:56.491+0000] {standard_task_runner.py:83} INFO - Job 21: Subtask process_NOAA_weather
[2025-10-24T01:04:56.522+0000] {task_command.py:388} INFO - Running <TaskInstance: data_pipeline_dag.process_NOAA_weather manual__2025-10-24T01:03:11.752846+00:00 [running]> on host d471b7381392
[2025-10-24T01:04:56.556+0000] {taskinstance.py:1509} INFO - Exporting the following env vars:
AIRFLOW_CTX_DAG_OWNER=***
AIRFLOW_CTX_DAG_ID=data_pipeline_dag
AIRFLOW_CTX_TASK_ID=process_NOAA_weather
AIRFLOW_CTX_EXECUTION_DATE=2025-10-24T01:03:11.752846+00:00
AIRFLOW_CTX_TRY_NUMBER=1
AIRFLOW_CTX_DAG_RUN_ID=manual__2025-10-24T01:03:11.752846+00:00
[2025-10-24T01:04:56.556+0000] {logging_mixin.py:137} INFO - 
Processing dataset: NOAA_weather
[2025-10-24T01:04:56.556+0000] {logging_mixin.py:137} INFO - Path does not exist: /opt/data_pipeline/data/raw/NOAA_weather
[2025-10-24T01:04:56.556+0000] {logging_mixin.py:137} INFO - ‚ùå FAILED: NOAA_weather - No data found in paths: ['/opt/data_pipeline/data/raw/NOAA_weather']
[2025-10-24T01:04:56.556+0000] {taskinstance.py:1768} ERROR - Task failed with exception
Traceback (most recent call last):
  File "/home/airflow/.local/lib/python3.7/site-packages/airflow/operators/python.py", line 175, in execute
    return_value = self.execute_callable()
  File "/home/airflow/.local/lib/python3.7/site-packages/airflow/operators/python.py", line 192, in execute_callable
    return self.python_callable(*self.op_args, **self.op_kwargs)
  File "/opt/airflow/dags/data_pipeline_dag.py", line 59, in load_and_process_dataset
    raise e
  File "/opt/airflow/dags/data_pipeline_dag.py", line 34, in load_and_process_dataset
    dataset_name=dataset["name"]
  File "/opt/airflow/dags/../scripts/data_loader.py", line 89, in load_data
    raise FileNotFoundError(f"No data found in paths: {data_paths}")
FileNotFoundError: No data found in paths: ['/opt/data_pipeline/data/raw/NOAA_weather']
[2025-10-24T01:04:56.732+0000] {taskinstance.py:1323} INFO - Marking task as FAILED. dag_id=data_pipeline_dag, task_id=process_NOAA_weather, execution_date=20251024T010311, start_date=20251024T010456, end_date=20251024T010456
[2025-10-24T01:04:56.739+0000] {standard_task_runner.py:105} ERROR - Failed to execute job 21 for task process_NOAA_weather (No data found in paths: ['/opt/data_pipeline/data/raw/NOAA_weather']; 338)
[2025-10-24T01:04:56.752+0000] {local_task_job.py:208} INFO - Task exited with return code 1
[2025-10-24T01:04:56.768+0000] {taskinstance.py:2578} INFO - 0 downstream tasks scheduled from follow-on schedule check
